<?xml version="1.0" encoding="UTF-8"?>
<testng-results total="4" passed="1" failed="2" skipped="1">
  <reporter-output>
    <line>
      <![CDATA[Added assertion for method]]>
    </line>
    <line>
      <![CDATA[Added assertion2 for method]]>
    </line>
  </reporter-output>
  <suite started-at="2020-01-27T12:54:40Z" name="DataProvider and listener" finished-at="2020-01-27T12:54:40Z" duration-ms="92">
    <groups>
      <group name="first">
        <method signature="CustomLoggingTest.testMethodTwo()" name="testMethodTwo" class="CustomLoggingTest"/>
        <method signature="CustomLoggingTest.testMethodThree()" name="testMethodThree" class="CustomLoggingTest"/>
        <method signature="CustomLoggingTest.testMethodOne()" name="testMethodOne" class="CustomLoggingTest"/>
        <method signature="CustomLoggingTest.MethodSix()" name="MethodSix" class="CustomLoggingTest"/>
      </group>
      <group name="second">
        <method signature="CustomLoggingTest.MethodSix()" name="MethodSix" class="CustomLoggingTest"/>
      </group>
    </groups>
    <test started-at="2020-01-27T12:54:40Z" name="Check LoggingTests" finished-at="2020-01-27T12:54:40Z" duration-ms="29">
      <class name="CustomLoggingTest">
        <test-method signature="testMethodTwo()" started-at="2020-01-27T12:54:40Z" name="testMethodTwo" finished-at="2020-01-27T12:54:40Z" duration-ms="6" status="FAIL">
          <exception class="java.lang.AssertionError">
            <message>
              <![CDATA[expected:<true> but was:<false>]]>
            </message>
            <full-stacktrace>
              <![CDATA[java.lang.AssertionError: expected:<true> but was:<false>
	at org.testng.Assert.fail(Assert.java:89)
	at org.testng.Assert.failNotEquals(Assert.java:480)
	at org.testng.Assert.assertTrue(Assert.java:37)
	at org.testng.Assert.assertTrue(Assert.java:47)
	at CustomLoggingTest.testMethodTwo(CustomLoggingTest.java:18)
	at java.base/jdk.internal.reflect.NativeMethodAccessorImpl.invoke0(Native Method)
	at java.base/jdk.internal.reflect.NativeMethodAccessorImpl.invoke(NativeMethodAccessorImpl.java:62)
	at java.base/jdk.internal.reflect.DelegatingMethodAccessorImpl.invoke(DelegatingMethodAccessorImpl.java:43)
	at java.base/java.lang.reflect.Method.invoke(Method.java:566)
	at org.testng.internal.MethodInvocationHelper.invokeMethod(MethodInvocationHelper.java:76)
	at org.testng.internal.Invoker.invokeMethod(Invoker.java:673)
	at org.testng.internal.Invoker.invokeTestMethod(Invoker.java:846)
	at org.testng.internal.Invoker.invokeTestMethods(Invoker.java:1170)
	at org.testng.internal.TestMethodWorker.invokeTestMethods(TestMethodWorker.java:125)
	at org.testng.internal.TestMethodWorker.run(TestMethodWorker.java:109)
	at java.base/java.util.concurrent.ThreadPoolExecutor.runWorker(ThreadPoolExecutor.java:1128)
	at java.base/java.util.concurrent.ThreadPoolExecutor$Worker.run(ThreadPoolExecutor.java:628)
	at java.base/java.lang.Thread.run(Thread.java:834)
]]>
            </full-stacktrace>
          </exception>
        </test-method>
        <test-method signature="MethodSix()" started-at="2020-01-27T12:54:40Z" name="MethodSix" finished-at="2020-01-27T12:54:40Z" duration-ms="0" status="FAIL">
          <exception class="java.lang.AssertionError">
            <message>
              <![CDATA[expected:<true> but was:<false>]]>
            </message>
            <full-stacktrace>
              <![CDATA[java.lang.AssertionError: expected:<true> but was:<false>
	at org.testng.Assert.fail(Assert.java:89)
	at org.testng.Assert.failNotEquals(Assert.java:480)
	at org.testng.Assert.assertTrue(Assert.java:37)
	at org.testng.Assert.assertTrue(Assert.java:47)
	at CustomLoggingTest.MethodSix(CustomLoggingTest.java:44)
	at java.base/jdk.internal.reflect.NativeMethodAccessorImpl.invoke0(Native Method)
	at java.base/jdk.internal.reflect.NativeMethodAccessorImpl.invoke(NativeMethodAccessorImpl.java:62)
	at java.base/jdk.internal.reflect.DelegatingMethodAccessorImpl.invoke(DelegatingMethodAccessorImpl.java:43)
	at java.base/java.lang.reflect.Method.invoke(Method.java:566)
	at org.testng.internal.MethodInvocationHelper.invokeMethod(MethodInvocationHelper.java:76)
	at org.testng.internal.Invoker.invokeMethod(Invoker.java:673)
	at org.testng.internal.Invoker.invokeTestMethod(Invoker.java:846)
	at org.testng.internal.Invoker.invokeTestMethods(Invoker.java:1170)
	at org.testng.internal.TestMethodWorker.invokeTestMethods(TestMethodWorker.java:125)
	at org.testng.internal.TestMethodWorker.run(TestMethodWorker.java:109)
	at java.base/java.util.concurrent.ThreadPoolExecutor.runWorker(ThreadPoolExecutor.java:1128)
	at java.base/java.util.concurrent.ThreadPoolExecutor$Worker.run(ThreadPoolExecutor.java:628)
	at java.base/java.lang.Thread.run(Thread.java:834)
]]>
            </full-stacktrace>
          </exception>
        </test-method>
        <test-method signature="testMethodThree()" started-at="2020-01-27T12:54:40Z" name="testMethodThree" finished-at="2020-01-27T12:54:40Z" depends-on-methods="CustomLoggingTest.testMethodTwo" duration-ms="1" status="SKIP">
        </test-method>
        <test-method signature="testMethodOne()" started-at="2020-01-27T12:54:40Z" name="testMethodOne" finished-at="2020-01-27T12:54:40Z" duration-ms="2" status="PASS">
        </test-method>
      </class>
    </test>
    <test started-at="2020-01-27T12:54:40Z" name="Test2" finished-at="2020-01-27T12:54:40Z" duration-ms="0">
    </test>
  </suite>
</testng-results>
